Workbook

Sheet интро
C3: Исследование выполнил: Александр Глебвский
C4: Данные сгенерированы ChatGPT и не являются NDA
C6: Задачи исследования | D6: № | E6: Декомпозиция | F6: Выводы исследования
C7: Анализ продаж продуктовых сетей | D7: 1 | E7: Динамика продаж по магазинам | F7: Проанализирован период с января 2023 по май 2024. Наблюдается общее снижение продаж в октябре 2023. По магазинам продаж: в Ашане видим рост продаж после июля 2023. В Дикси - провал воктябре 2023. В Пятерочке - максимум в августе 2023, а спады заметны в мае и декабре 2023
D8: 2 | E8: Анализ цен внутри товарной категории по магазинам | F8: В Пятерочке - наибольший дисконт - 10%, в Ленте наценка 13%
D9: 3 | E9: Суммарные продажи по магазинам | F9: По сумме продаж лидирует O'Key, отстает Билла
C10: Сравнение поставщиков по объемам закупок | D10: 4 | E10: Анализ цен внутри категории по поставщикам | F10: Максимальная цена макарон в ПастаЗара
D11: 5 | E11: Суммарные продажи по поставщикам | F11: Лидирует Паста Зара, отстает Вим БильДан
C12: Изучение продаж по категориям товаров | D12: 6 | E12: Суммарные продажи по категориям | F12: Лидируют макароны и конфты, отстает колбаса
D13: 7 | E13: Среднее кол-во по категориям (что покупают чаще) | F13: В чеке в среднем 3 штуки в каждой категории
C14: Изучение клиентов по географии и лайфтайму | D14: 8 | E14: Аналитика географии клиентов | F14: Большинство клиентов из России, меньшинство из Беларси
D15: 9 | E15: Кол-во дней с момента регистрациидо покупки | F15: среднее - 1.5 гола (450 - 550 дней)
D16: 10 | E16: Лайфтайм клиента | F16: Средий лайфтайм - около 3-х лет
D17: 11 | E17: Частотность имен для рекламной компании | F17: 70% имен использутся по 5 раз
D18: 12 | E18: Платежеспособность по странам | F18: Россия показывает наибольшую платежжеспособность, Белорусь - наименьшую
C20: Отработка Hard Skills
C21: Преобразование типов и визуальное форматирование
C22: Условное форматирование данных
C23: Умные таблицы и работа с абсолютными и относительными ссылками
C24: Математические и текстовые функции
C25: Функции для работы с датой и временем
C26: Функции поиска и извлечения данных
C27: Сводные таблицы и срезы данных
C28: Построение диаграмм

Sheet Гафики

Sheet Динамика продаж
A1: магазин покупки | B1: Пятерочка
A3: Названия строк | B3: Сумма по полю сумма чека
A4: 2023 | B4: 19503
A5: янв | B5: 963
A6: фев | B6: 1185
A7: мар | B7: 2444
A8: апр | B8: 448
A9: май | B9: 460
A10: июн | B10: 2898
A11: июл | B11: 2715
A12: авг | B12: 3967
A13: сен | B13: 2378
A14: окт | B14: 1397
A15: дек | B15: 648
... A21: Общий итог | B21: 27662
D24: Проанализирован период с января 2023 по май 2024. Наблюдается общее снижение продаж в октябре 2023.
D25: По магазинам продаж: в Ашане видим рост продаж после июля 2023
D26: В Дикси - провал в октябре 2023
D27: В Пятерочке - максимум в августе 2023, а спады заметны в мае и декабре 2023

Sheet Выгода клиента
A3: Названия строк | B3: Среднее по полю Выгода клиента
A4: Лента | B4: 0.13314535
A5: Городской Супермаркет | B5: 0.065458688
A6: Метро | B6: 0.047852649
A7: Билла | B7: 0.04577719
A8: Азбука Вкуса | B8: 0.04213556
A9: Седьмой Континент | B9: 0.039584188
A10: Ароматный Мир | B10: 0.026621364
A11: Мосмарт | B11: 0.019548995
A12: Мираторг | B12: 0.0043236685
A13: Ашан | B13: -0.0089704365
A14: Бристоль | B14: -0.011007391
A15: Магнит | B15: -0.024982716
... A23: Спар | B23: -0.066618319
D25: В Пятерочке - наибольший дисконт - 10%, в Ленте наценка 10%

Sheet GMV Продажи по магазинам
A3: Названия строк | B3: GMV
A4: О'кей | B4: 52844
A5: Гиперглобус | B5: 51789
A6: Мосмарт | B6: 49580
A7: Спар | B7: 48746
A8: Верный | B8: 47028
A9: Городской Супермаркет | B9: 43098
A10: Ароматный Мир | B10: 42837
A11: Седьмой Континент | B11: 41106
A12: Бристоль | B12: 41010
A13: Мираторг | B13: 40029
A14: Метро | B14: 39168
A15: Лента | B15: 38312
... A24: Общий итог | B24: 800433
D25: По сумме продаж лидирует O'Key, отстает Билла

Sheet Подробности2
A1: Сведения о Среднее по полю средняя стоимость в категории по поставщику. - Выгода для клиента внутри поставщика.: -0.991794471036436
A3: id чека | B3: id товара | C3: цена за шт в рублях | D3: кол-во штук в чеке | E3: сумма чека | F3: дата создания чека | G3: магазин покупки | H3: id клиента | I3: Категория товара | J3: Поставщик | K3: Средняя цена в категории за штуку | L3: Выгода клиента | M3: средняя стоимость в категории по поставщику. | N3: Выгода для клиента внутри поставщика.
A4: 682 | B4: 110 | C4: 84 | D4: 5 | E4: 420 | F4: 45029 | G4: Карусель | H4: 225 | I4: Макароны | J4: Паста Зара | K4: 265.47674 | L4: -0.6835881 | M4: 10237 | N4: -0.99179447

Sheet Средн. стоим в кат по поставщ. 
A1: Категория товара | B1: (Все)
A3: Названия строк | B3: Среднее по полю средняя стоимость в категории по поставщику.
A4: Estrella | B4: 2929
A5: Green Garden | B5: 1846
A6: Greenfield | B6: 6412
A7: Hochland | B7: 504
A8: Jacobs | B8: 5248
A9: Lay's | B9: 2244
A10: Lipton | B10: 4943
A11: Nescafe | B11: 2569
A12: President | B12: 3935
A13: Pringles | B13: 5885
A14: Rich | B14: 1089
A15: Tchibo | B15: 420
... A26: Борилла | B26: 6852
A27: Вимм-Билль-Данн | B27: 387 | C27: Максимальная цена макарон в ПастаЗара
A28: Гавриш | B28: 2229
A29: Дарница | B29: 1848
A30: Добрый | B30: 2671
A31: Домик в деревне | B31: 4946
A32: Дымов | B32: 2814
A33: Зеленая грядка | B33: 796
A34: Илецкая | B34: 4287
A35: Каравай | B35: 3974
A36: Карат | B36: 2802
A37: КДВ | B37: 4200
A38: Красный Октябрь | B38: 2189
A39: Макфа | B39: 3622
... A82: Общий итог | B82: 4445.66

Sheet Выгода для клиента внутри поста
A1: Категория товара | B1: (Все)
A3: Названия строк | B3: Среднее по полю Выгода для клиента внутри поставщика.
A4: Микоян | B4: 0
A5: Вимм-Билль-Данн | B5: -0.5
A6: Русское море | B6: -0.66666667
A7: Hochland | B7: -0.66666667
A8: Tchibo | B8: -0.66666667
A9: Черкизово | B9: -0.75
A10: Националь | B10: -0.75
A11: Rich | B11: -0.75
A12: Тесс | B12: -0.75
A13: Green Garden | B13: -0.8
A14: Зеленая грядка | B14: -0.8
A15: Активиа | B15: -0.83333333
... A82: Общий итог | B82: -0.92

Sheet Суммарные продажи по поставщика
A3: Названия строк | B3: Сумма по полю сумма чека
A4: Паста Зара | B4: 29430
A5: Фруктовый сад | B5: 24872
A6: Сырная долина | B6: 24200
A7: Greenfield | B7: 21191
A8: Бабаевский | B8: 20462
A9: Борилла | B9: 20345
A10: Домик в деревне | B10: 18739
A11: Pringles | B11: 18368
A12: Белый Злат | B12: 17471
A13: Рот Фронт | B13: 16874
A14: Jacobs | B14: 15751
A15: Овощной ряд | B15: 15581
... A21: Русский сахар | B21: 13106
A22: Хлебный Дом | B22: 13056 | E22: Лидирует Паста Зара, отстает Вим БильДан
A23: Мираторг | B23: 12899
A24: Эрманн | B24: 12851
A25: Илецкая | B25: 12813
A26: Русский Хлеб | B26: 12712
A27: Белогорье | B27: 12474
A28: Сладов | B28: 12078
A29: Экстра | B29: 11937
A30: President | B30: 11845
A31: Беллакт | B31: 11630
A32: Экзотик | B32: 11100
A33: Салта | B33: 10813
A34: Простоквашино | B34: 10714
... A82: Общий итог | B82: 800433

Sheet Подробности3
A1: Сведения о Среднее по полю кол-во штук в чеке - Категория товара: Йогурт
A3: id чека | B3: id товара | C3: цена за шт в рублях | D3: кол-во штук в чеке | E3: сумма чека | F3: дата создания чека | G3: магазин покупки | H3: id клиента | I3: Категория товара | J3: Поставщик | K3: Средняя цена в категории за штуку | L3: Выгода клиента | M3: средняя стоимость в категории по поставщику. | N3: Выгода для клиента внутри поставщика.
A4: 984 | B4: 404 | C4: 304 | D4: 5 | E4: 1520 | F4: 45288 | G4: Верный | H4: 17 | I4: Йогурт | J4: Ростагроэкспорт | K4: 263.25424 | L4: 0.15477723 | M4: 5929 | N4: -0.9487266
A5: 964 | B5: 448 | C5: 484 | D5: 1 | E5: 484 | F5: 45301 | G5: Городской Супермаркет | H5: 404 | I5: Йогурт | J5: Ростагроэкспорт | K5: 263.25424 | L5: 0.83852691 | M5: 5929 | N5: -0.91836735
A6: 943 | B6: 447 | C6: 118 | D6: 3 | E6: 354 | F6: 45337 | G6: Перекресток | H6: 9 | I6: Йогурт | J6: Эрманн | K6: 263.25424 | L6: -0.5517641 | M6: 4970 | N6: -0.97625755
A7: 935 | B7: 9 | C7: 321 | D7: 1 | E7: 321 | F7: 45173 | G7: Ароматный Мир | H7: 217 | I7: Йогурт | J7: Чудо | K7: 263.25424 | L7: 0.21935359 | M7: 2871 | N7: -0.88819227
A8: 925 | B8: 46 | C8: 290 | D8: 3 | E8: 870 | F8: 45059 | G8: Карусель | H8: 460 | I8: Йогурт | J8: Активиа | K8: 263.25424 | L8: 0.1015967 | M8: 1762 | N8: -0.8354143
A9: 923 | B9: 465 | C9: 71 | D9: 5 | E9: 355 | F9: 45253 | G9: Перекресток | H9: 321 | I9: Йогурт | J9: Ростагроэкспорт | K9: 263.25424 | L9: -0.73029874 | M9: 5929 | N9: -0.98802496
A10: 913 | B10: 465 | C10: 177 | D10: 1 | E10: 177 | F10: 45122 | G10: Перекресток | H10: 167 | I10: Йогурт | J10: Ростагроэкспорт | K10: 263.25424 | L10: -0.32764615 | M10: 5929 | N10: -0.97014674
A11: 902 | B11: 444 | C11: 328 | D11: 3 | E11: 984 | F11: 45102 | G11: Азбука Вкуса | H11: 292 | I11: Йогурт | J11: Эрманн | K11: 263.25424 | L11: 0.24594386 | M11: 4970 | N11: -0.93400402
A12: 855 | B12: 239 | C12: 397 | D12: 2 | E12: 794 | F12: 45398 | G12: Мираторг | H12: 65 | I12: Йогурт | J12: Эрманн | K12: 263.25424 | L12: 0.5080479 | M12: 4970 | N12: -0.92012072
A13: 10 | B13: 100 | C13: 449 | D13: 2 | E13: 898 | F13: 45032 | G13: Карусель | H13: 413 | I13: Йогурт | J13: Ростагроэкспорт | K13: 263.25424 | L13: 0.70557559 | M13: 5929 | N13: -0.92427053
A14: 848 | B14: 319 | C14: 193 | D14: 1 | E14: 193 | F14: 45396 | G14: Мосмарт | H14: 43 | I14: Йогурт | J14: Эрманн | K14: 263.25424 | L14: -0.2668684 | M14: 4970 | N14: -0.961167
A15: 837 | B15: 104 | C15: 420 | D15: 2 | E15: 840 | F15: 45427 | G15: Городской Супермаркет | H15: 26 | I15: Йогурт | J15: Ростагроэкспорт | K15: 263.25424 | L15: 0.59541592 | M15: 5929 | N15: -0.92916175
... A62: 62 | B62: 465 | C62: 311 | D62: 2 | E62: 622 | F62: 44934 | G62: Дикси | H62: 14 | I62: Йогурт | J62: Ростагроэкспорт | K62: 263.25424 | L62: 0.1813675 | M62: 5929 | N62: -0.94754596

Sheet Средн_кол-во_штук_в_чеке_по_кат
A3: Названия строк | B3: Среднее по полю кол-во штук в чеке
A4: Йогурт | B4: 2.7627119
A5: Колбаса | B5: 2.8846154
A6: Конфеты | B6: 2.983871
A7: Кофе | B7: 3.047619
A8: Крупа | B8: 2.7209302
A9: Макароны | B9: 2.9418605
A10: Молоко | B10: 3.2380952
A11: Мясо | B11: 3.1272727
A12: Овощи | B12: 3.1463415
A13: Печенье | B13: 3.0638298
A14: Рис | B14: 3.1875
A15: Рыба | B15: 3.1282051
... A20: Фрукты | B20: 2.9534884
A21: Хлеб | B21: 3.0909091 | F21: В чеке в среднем 3 штуки в каждой категории
A22: Чай | B22: 2.9272727
A23: Чипсы | B23: 3.0588235
A24: Общий итог | B24: 2.99

Sheet продажи по категориям
A3: Названия строк | B3: Сумма по полю сумма чека
A4: Макароны | B4: 66945
A5: Конфеты | B5: 48797
A6: Мясо | B6: 47223
A7: Сок | B7: 45862
A8: Чипсы | B8: 44539
A9: Сахар | B9: 44513
A10: Соль | B10: 44468
A11: Сыр | B11: 43903
A12: Чай | B12: 43626
A13: Хлеб | B13: 42352
A14: Молоко | B14: 42165
A15: Йогурт | B15: 41745
... A21: Крупа | B21: 28053
A22: Рис | B22: 27375 | D22: Лидируют макароны и конфты, отстает колбаса
A23: Колбаса | B23: 21313
A24: Общий итог | B24: 800433

Sheet Платежеспособность по странам
A3: Названия строк | B3: Сумма по полю сумма чека
A4: Россия | B4: 251330
A5: Узбекистан | B5: 163294
A6: Украина | B6: 147543
A7: Таджикистан | B7: 139473
A8: Беларусь | B8: 98793
A9: Общий итог | B9: 800433
D20: Россия показывает наибольшую платежжеспособность
D21: Белорус - наименьшую

Sheet Кол-во дней с момента регистр

Sheet Лайфтайм клиента

Sheet продажи
A1: id чека | B1: id товара | C1: цена за шт в рублях | D1: кол-во штук в чеке | E1: сумма чека | F1: дата создания чека | G1: магазин покупки | H1: id клиента | I1: Категория товара | J1: Поставщик | K1: Средняя цена в категории за штуку | L1: Выгода клиента | M1: средняя стоимость в категории по поставщику. | N1: Выгода для клиента внутри поставщика. | O1: Дата регистрации клента | P1: Кол-во дней с момента регистрации | Q1: Текущая дата | R1: Лайфтайм клиента | S1: Страна | T1: Столбец2
A2: 1 | B2: 300 | C2: 103 | D2: 4 | E2: 412 | F2: 45187 | G2: Бристоль | H2: 315 | I2: =VLOOKUP(продажи!$B2,товар!$A$1:$C$433,2) -> Сахар | J2: =VLOOKUP(B2,товар!$A$1:$C$433,3) -> Продимекс | K2: =AVERAGEIF(продажи!$I$2:$I$1001,продажи!$I$2:$I$1001,продажи!$C$2:$C$1001) -> 254.58333 | L2: =продажи!$C2/продажи!$K2-1 -> -0.59541735 | M2: =SUMIFS($C$2:$C$1001,$I$2:$I$1001,I2,$J$2:$J$1001,J2) -> 5172 | N2: =Таблица1[[#This Row],[цена за шт в рублях]]/Таблица1[[#This Row],[средняя стоимость в категории по поставщику.]]-1 -> -0.98008507 | O2: =VLOOKUP(Таблица1[[#This Row],[id клиента]],клиенты!$A$2:$E$435,5,0) -> 44747 | P2: =Таблица1[[#This Row],[дата создания чека]]-Таблица1[[#This Row],[Дата регистрации клента]] -> 440 | Q2: =TODAY() -> 46059 | R2: =(TODAY()-Таблица1[[#This Row],[Дата регистрации клента]])/30 -> 43.733333 | S2: =VLOOKUP(Таблица1[[#This Row],[id клиента]],Таблица8[[id клиента]:[Страна]],7,0) -> Узбекистан
A3: 2 | B3: 486 | C3: 296 | D3: 3 | E3: 888 | F3: 45083 | G3: Дикси | H3: 253 | I3: =VLOOKUP(продажи!$B3,товар!$A$1:$C$433,2) -> Соль | J3: =VLOOKUP(B3,товар!$A$1:$C$433,3) -> Илецкая | K3: =AVERAGEIF(продажи!$I$2:$I$1001,продажи!$I$2:$I$1001,продажи!$C$2:$C$1001) -> 264.86792 | L3: =продажи!$C3/продажи!$K3-1 -> 0.11753811 | M3: =SUMIFS($C$2:$C$1001,$I$2:$I$1001,I3,$J$2:$J$1001,J3) -> 4287 | N3: =Таблица1[[#This Row],[цена за шт в рублях]]/Таблица1[[#This Row],[средняя стоимость в категории по поставщику.]]-1 -> -0.93095405 | O3: =VLOOKUP(Таблица1[[#This Row],[id клиента]],клиенты!$A$2:$E$435,5,0) -> 44750 | P3: =Таблица1[[#This Row],[дата создания чека]]-Таблица1[[#This Row],[Дата регистрации клента]] -> 333 | Q3: =TODAY() -> 46059 | R3: =(TODAY()-Таблица1[[#This Row],[Дата регистрации клента]])/30 -> 43.633333 | S3: =VLOOKUP(Таблица1[[#This Row],[id клиента]],Таблица8[[id клиента]:[Страна]],7,0) -> Беларусь
A4: 3 | B4: 76 | C4: 139 | D4: 5 | E4: 695 | F4: 45363 | G4: Городской Супермаркет | H4: 12 | I4: =VLOOKUP(продажи!$B4,товар!$A$1:$C$433,2) -> Печенье | J4: =VLOOKUP(B4,товар!$A$1:$C$433,3) -> Юбилейное | K4: =AVERAGEIF(продажи!$I$2:$I$1001,продажи!$I$2:$I$1001,продажи!$C$2:$C$1001) -> 283.46809 | L4: =продажи!$C4/продажи!$K4-1 -> -0.50964497 | M4: =SUMIFS($C$2:$C$1001,$I$2:$I$1001,I4,$J$2:$J$1001,J4) -> 2092 | N4: =Таблица1[[#This Row],[цена за шт в рублях]]/Таблица1[[#This Row],[средняя стоимость в категории по поставщику.]]-1 -> -0.93355641 | O4: =VLOOKUP(Таблица1[[#This Row],[id клиента]],клиенты!$A$2:$E$435,5,0) -> 44842 | P4: =Таблица1[[#This Row],[дата создания чека]]-Таблица1[[#This Row],[Дата регистрации клента]] -> 521 | Q4: =TODAY() -> 46059 | R4: =(TODAY()-Таблица1[[#This Row],[Дата регистрации клента]])/30 -> 40.566667 | S4: =VLOOKUP(Таблица1[[#This Row],[id клиента]],Таблица8[[id клиента]:[Страна]],7,0) -> Беларусь
A5: 4 | B5: 240 | C5: 141 | D5: 5 | E5: 705 | F5: 45262 | G5: Верный | H5: 116 | I5: =VLOOKUP(продажи!$B5,товар!$A$1:$C$433,2) -> Макароны | J5: =VLOOKUP(B5,товар!$A$1:$C$433,3) -> Борилла | K5: =AVERAGEIF(продажи!$I$2:$I$1001,продажи!$I$2:$I$1001,продажи!$C$2:$C$1001) -> 265.47674 | L5: =продажи!$C5/продажи!$K5-1 -> -0.46888003 | M5: =SUMIFS($C$2:$C$1001,$I$2:$I$1001,I5,$J$2:$J$1001,J5) -> 6852 | N5: =Таблица1[[#This Row],[цена за шт в рублях]]/Таблица1[[#This Row],[средняя стоимость в категории по поставщику.]]-1 -> -0.97942207 | O5: =VLOOKUP(Таблица1[[#This Row],[id клиента]],клиенты!$A$2:$E$435,5,0) -> 44643 | P5: =Таблица1[[#This Row],[дата создания чека]]-Таблица1[[#This Row],[Дата регистрации клента]] -> 619 | Q5: =TODAY() -> 46059 | R5: =(TODAY()-Таблица1[[#This Row],[Дата регистрации клента]])/30 -> 47.2 | S5: =VLOOKUP(Таблица1[[#This Row],[id клиента]],Таблица8[[id клиента]:[Страна]],7,0) -> Россия
A6: 5 | B6: 32 | C6: 123 | D6: 2 | E6: 246 | F6: 45151 | G6: Спар | H6: 471 | I6: =VLOOKUP(продажи!$B6,товар!$A$1:$C$433,2) -> Овощи | J6: =VLOOKUP(B6,товар!$A$1:$C$433,3) -> Зеленая грядка | K6: =AVERAGEIF(продажи!$I$2:$I$1001,продажи!$I$2:$I$1001,продажи!$C$2:$C$1001) -> 250.4878 | L6: =продажи!$C6/продажи!$K6-1 -> -0.50895813 | M6: =SUMIFS($C$2:$C$1001,$I$2:$I$1001,I6,$J$2:$J$1001,J6) -> 796 | N6: =Таблица1[[#This Row],[цена за шт в рублях]]/Таблица1[[#This Row],[средняя стоимость в категории по поставщику.]]-1 -> -0.84547739 | O6: =VLOOKUP(Таблица1[[#This Row],[id клиента]],клиенты!$A$2:$E$435,5,0) -> 44577 | P6: =Таблица1[[#This Row],[дата создания чека]]-Таблица1[[#This Row],[Дата регистрации клента]] -> 574 | Q6: =TODAY() -> 46059 | R6: =(TODAY()-Таблица1[[#This Row],[Дата регистрации клента]])/30 -> 49.4 | S6: =VLOOKUP(Таблица1[[#This Row],[id клиента]],Таблица8[[id клиента]:[Страна]],7,0) -> Украина
A7: 6 | B7: 162 | C7: 452 | D7: 2 | E7: 904 | F7: 45281 | G7: Бристоль | H7: 374 | I7: =VLOOKUP(продажи!$B7,товар!$A$1:$C$433,2) -> Сок | J7: =VLOOKUP(B7,товар!$A$1:$C$433,3) -> Фруктовый сад | K7: =AVERAGEIF(продажи!$I$2:$I$1001,продажи!$I$2:$I$1001,продажи!$C$2:$C$1001) -> 268.60345 | L7: =продажи!$C7/продажи!$K7-1 -> 0.6827781 | M7: =SUMIFS($C$2:$C$1001,$I$2:$I$1001,I7,$J$2:$J$1001,J7) -> 9023 | N7: =Таблица1[[#This Row],[цена за шт в рублях]]/Таблица1[[#This Row],[средняя стоимость в категории по поставщику.]]-1 -> -0.9499058 | O7: =VLOOKUP(Таблица1[[#This Row],[id клиента]],клиенты!$A$2:$E$435,5,0) -> 44582 | P7: =Таблица1[[#This Row],[дата создания чека]]-Таблица1[[#This Row],[Дата регистрации клента]] -> 699 | Q7: =TODAY() -> 46059 | R7: =(TODAY()-Таблица1[[#This Row],[Дата регистрации клента]])/30 -> 49.233333 | S7: =VLOOKUP(Таблица1[[#This Row],[id клиента]],Таблица8[[id клиента]:[Страна]],7,0) -> Украина
A8: 7 | B8: 323 | C8: 149 | D8: 5 | E8: 745 | F8: 45349 | G8: Карусель | H8: 477 | I8: =VLOOKUP(продажи!$B8,товар!$A$1:$C$433,2) -> Рыба | J8: =VLOOKUP(B8,товар!$A$1:$C$433,3) -> Меридиан | K8: =AVERAGEIF(продажи!$I$2:$I$1001,продажи!$I$2:$I$1001,продажи!$C$2:$C$1001) -> 258.51282 | L8: =продажи!$C8/продажи!$K8-1 -> -0.42362626 | M8: =SUMIFS($C$2:$C$1001,$I$2:$I$1001,I8,$J$2:$J$1001,J8) -> 4431 | N8: =Таблица1[[#This Row],[цена за шт в рублях]]/Таблица1[[#This Row],[средняя стоимость в категории по поставщику.]]-1 -> -0.96637328 | O8: =VLOOKUP(Таблица1[[#This Row],[id клиента]],клиенты!$A$2:$E$435,5,0) -> 44738 | P8: =Таблица1[[#This Row],[дата создания чека]]-Таблица1[[#This Row],[Дата регистрации клента]] -> 611 | Q8: =TODAY() -> 46059 | R8: =(TODAY()-Таблица1[[#This Row],[Дата регистрации клента]])/30 -> 44.033333 | S8: =VLOOKUP(Таблица1[[#This Row],[id клиента]],Таблица8[[id клиента]:[Страна]],7,0) -> Узбекистан
A9: 8 | B9: 60 | C9: 489 | D9: 4 | E9: 1956 | F9: 45327 | G9: Мираторг | H9: 335 | I9: =VLOOKUP(продажи!$B9,товар!$A$1:$C$433,2) -> Кофе | J9: =VLOOKUP(B9,товар!$A$1:$C$433,3) -> Jacobs | K9: =AVERAGEIF(продажи!$I$2:$I$1001,продажи!$I$2:$I$1001,продажи!$C$2:$C$1001) -> 249.02381 | L9: =продажи!$C9/продажи!$K9-1 -> 0.96366765 | M9: =SUMIFS($C$2:$C$1001,$I$2:$I$1001,I9,$J$2:$J$1001,J9) -> 5248 | N9: =Таблица1[[#This Row],[цена за шт в рублях]]/Таблица1[[#This Row],[средняя стоимость в категории по поставщику.]]-1 -> -0.90682165 | O9: =VLOOKUP(Таблица1[[#This Row],[id клиента]],клиенты!$A$2:$E$435,5,0) -> 44619 | P9: =Таблица1[[#This Row],[дата создания чека]]-Таблица1[[#This Row],[Дата регистрации клента]] -> 708 | Q9: =TODAY() -> 46059 | R9: =(TODAY()-Таблица1[[#This Row],[Дата регистрации клента]])/30 -> 48 | S9: =VLOOKUP(Таблица1[[#This Row],[id клиента]],Таблица8[[id клиента]:[Страна]],7,0) -> Узбекистан
A10: 9 | B10: 401 | C10: 416 | D10: 5 | E10: 2080 | F10: 45376 | G10: Мосмарт | H10: 350 | I10: =VLOOKUP(продажи!$B10,товар!$A$1:$C$433,2) -> Чай | J10: =VLOOKUP(B10,товар!$A$1:$C$433,3) -> Greenfield | K10: =AVERAGEIF(продажи!$I$2:$I$1001,продажи!$I$2:$I$1001,продажи!$C$2:$C$1001) -> 271.18182 | L10: =продажи!$C10/продажи!$K10-1 -> 0.53402615 | M10: =SUMIFS($C$2:$C$1001,$I$2:$I$1001,I10,$J$2:$J$1001,J10) -> 6412 | N10: =Таблица1[[#This Row],[цена за шт в рублях]]/Таблица1[[#This Row],[средняя стоимость в категории по поставщику.]]-1 -> -0.93512165 | O10: =VLOOKUP(Таблица1[[#This Row],[id клиента]],клиенты!$A$2:$E$435,5,0) -> 44684 | P10: =Таблица1[[#This Row],[дата создания чека]]-Таблица1[[#This Row],[Дата регистрации клента]] -> 692 | Q10: =TODAY() -> 46059 | R10: =(TODAY()-Таблица1[[#This Row],[Дата регистрации клента]])/30 -> 45.833333 | S10: =VLOOKUP(Таблица1[[#This Row],[id клиента]],Таблица8[[id клиента]:[Страна]],7,0) -> Украина
A11: 10 | B11: 100 | C11: 449 | D11: 2 | E11: 898 | F11: 45032 | G11: Карусель | H11: 413 | I11: =VLOOKUP(продажи!$B11,товар!$A$1:$C$433,2) -> Йогурт | J11: =VLOOKUP(B11,товар!$A$1:$C$433,3) -> Ростагроэкспорт | K11: =AVERAGEIF(продажи!$I$2:$I$1001,продажи!$I$2:$I$1001,продажи!$C$2:$C$1001) -> 263.25424 | L11: =продажи!$C11/продажи!$K11-1 -> 0.70557559 | M11: =SUMIFS($C$2:$C$1001,$I$2:$I$1001,I11,$J$2:$J$1001,J11) -> 5929 | N11: =Таблица1[[#This Row],[цена за шт в рублях]]/Таблица1[[#This Row],[средняя стоимость в категории по поставщику.]]-1 -> -0.92427053 | O11: =VLOOKUP(Таблица1[[#This Row],[id клиента]],клиенты!$A$2:$E$435,5,0) -> 44699 | P11: =Таблица1[[#This Row],[дата создания чека]]-Таблица1[[#This Row],[Дата регистрации клента]] -> 333 | Q11: =TODAY() -> 46059 | R11: =(TODAY()-Таблица1[[#This Row],[Дата регистрации клента]])/30 -> 45.333333 | S11: =VLOOKUP(Таблица1[[#This Row],[id клиента]],Таблица8[[id клиента]:[Страна]],7,0) -> Россия
A12: 11 | B12: 217 | C12: 296 | D12: 2 | E12: 592 | F12: 45136 | G12: Карусель | H12: 495 | I12: =VLOOKUP(продажи!$B12,товар!$A$1:$C$433,2) -> Мясо | J12: =VLOOKUP(B12,товар!$A$1:$C$433,3) -> Агрокомплекс | K12: =AVERAGEIF(продажи!$I$2:$I$1001,продажи!$I$2:$I$1001,продажи!$C$2:$C$1001) -> 271.74545 | L12: =продажи!$C12/продажи!$K12-1 -> 0.08925465 | M12: =SUMIFS($C$2:$C$1001,$I$2:$I$1001,I12,$J$2:$J$1001,J12) -> 3112 | N12: =Таблица1[[#This Row],[цена за шт в рублях]]/Таблица1[[#This Row],[средняя стоимость в категории по поставщику.]]-1 -> -0.90488432 | O12: =VLOOKUP(Таблица1[[#This Row],[id клиента]],клиенты!$A$2:$E$435,5,0) -> 44654 | P12: =Таблица1[[#This Row],[дата создания чека]]-Таблица1[[#This Row],[Дата регистрации клента]] -> 482 | Q12: =TODAY() -> 46059 | R12: =(TODAY()-Таблица1[[#This Row],[Дата регистрации клента]])/30 -> 46.833333 | S12: =VLOOKUP(Таблица1[[#This Row],[id клиента]],Таблица8[[id клиента]:[Страна]],7,0) -> Узбекистан
A13: 12 | B13: 445 | C13: 109 | D13: 5 | E13: 545 | F13: 45394 | G13: Мираторг | H13: 353 | I13: =VLOOKUP(продажи!$B13,товар!$A$1:$C$433,2) -> Сахар | J13: =VLOOKUP(B13,товар!$A$1:$C$433,3) -> Сладов | K13: =AVERAGEIF(продажи!$I$2:$I$1001,продажи!$I$2:$I$1001,продажи!$C$2:$C$1001) -> 254.58333 | L13: =продажи!$C13/продажи!$K13-1 -> -0.57184943 | M13: =SUMIFS($C$2:$C$1001,$I$2:$I$1001,I13,$J$2:$J$1001,J13) -> 3604 | N13: =Таблица1[[#This Row],[цена за шт в рублях]]/Таблица1[[#This Row],[средняя стоимость в категории по поставщику.]]-1 -> -0.96975583 | O13: =VLOOKUP(Таблица1[[#This Row],[id клиента]],клиенты!$A$2:$E$435,5,0) -> 44656 | P13: =Таблица1[[#This Row],[дата создания чека]]-Таблица1[[#This Row],[Дата регистрации клента]] -> 738 | Q13: =TODAY() -> 46059 | R13: =(TODAY()-Таблица1[[#This Row],[Дата регистрации клента]])/30 -> 46.766667 | S13: =VLOOKUP(Таблица1[[#This Row],[id клиента]],Таблица8[[id клиента]:[Страна]],7,0) -> Таджикистан
... A25: 24 | B25: 451 | C25: 161 | D25: 4 | E25: 644 | F25: 44966 | G25: Мосмарт | H25: 39 | I25: =VLOOKUP(продажи!$B25,товар!$A$1:$C$433,2) -> Рис | J25: =VLOOKUP(B25,товар!$A$1:$C$433,3) -> Белый Злат | K25: =AVERAGEIF(продажи!$I$2:$I$1001,продажи!$I$2:$I$1001,продажи!$C$2:$C$1001) -> 258.375 | L25: =продажи!$C25/продажи!$K25-1 -> -0.3768747 | M25: =SUMIFS($C$2:$C$1001,$I$2:$I$1001,I25,$J$2:$J$1001,J25) -> 4585 | N25: =Таблица1[[#This Row],[цена за шт в рублях]]/Таблица1[[#This Row],[средняя стоимость в категории по поставщику.]]-1 -> -0.9648855 | O25: =VLOOKUP(Таблица1[[#This Row],[id клиента]],клиенты!$A$2:$E$435,5,0) -> 44653 | P25: =Таблица1[[#This Row],[дата создания чека]]-Таблица1[[#This Row],[Дата регистрации клента]] -> 313 | Q25: =TODAY() -> 46059 | R25: =(TODAY()-Таблица1[[#This Row],[Дата регистрации клента]])/30 -> 46.866667 | S25: =VLOOKUP(Таблица1[[#This Row],[id клиента]],Таблица8[[id клиента]:[Страна]],7,0) -> Беларусь
A26: 25 | B26: 7 | C26: 362 | D26: 1 | E26: 362 | F26: 45326 | G26: Спар | H26: 303 | I26: =VLOOKUP(B2,товар!$A$1:$C$433,2) -> Сахар | J26: =VLOOKUP(B2,товар!$A$1:$C$433,3) -> Продимекс | K26: =AVERAGEIF(продажи!$I$2:$I$1001,продажи!$I$2:$I$1001,продажи!$C$2:$C$1001) -> 254.58333 | L26: =продажи!$C26/продажи!$K26-1 -> 0.42193126 | M26: =SUMIFS($C$2:$C$1001,$I$2:$I$1001,I26,$J$2:$J$1001,J26) -> 5172 | N26: =Таблица1[[#This Row],[цена за шт в рублях]]/Таблица1[[#This Row],[средняя стоимость в категории по поставщику.]]-1 -> -0.93000773 | O26: =VLOOKUP(Таблица1[[#This Row],[id клиента]],клиенты!$A$2:$E$435,5,0) -> 44689 | P26: =Таблица1[[#This Row],[дата создания чека]]-Таблица1[[#This Row],[Дата регистрации клента]] -> 637 | Q26: =TODAY() -> 46059 | R26: =(TODAY()-Таблица1[[#This Row],[Дата регистрации клента]])/30 -> 45.666667 | S26: =VLOOKUP(Таблица1[[#This Row],[id клиента]],Таблица8[[id клиента]:[Страна]],7,0) -> Узбекистан
A27: 26 | B27: 495 | C27: 312 | D27: 1 | E27: 312 | F27: 45174 | G27: Перекресток | H27: 422 | I27: =VLOOKUP(продажи!$B27,товар!$A$1:$C$433,2) -> Чай | J27: =VLOOKUP(B27,товар!$A$1:$C$433,3) -> Greenfield | K27: =AVERAGEIF(продажи!$I$2:$I$1001,продажи!$I$2:$I$1001,продажи!$C$2:$C$1001) -> 271.18182 | L27: =продажи!$C27/продажи!$K27-1 -> 0.15051961 | M27: =SUMIFS($C$2:$C$1001,$I$2:$I$1001,I27,$J$2:$J$1001,J27) -> 6412 | N27: =Таблица1[[#This Row],[цена за шт в рублях]]/Таблица1[[#This Row],[средняя стоимость в категории по поставщику.]]-1 -> -0.95134124 | O27: =VLOOKUP(Таблица1[[#This Row],[id клиента]],клиенты!$A$2:$E$435,5,0) -> 44784 | P27: =Таблица1[[#This Row],[дата создания чека]]-Таблица1[[#This Row],[Дата регистрации клента]] -> 390 | Q27: =TODAY() -> 46059 | R27: =(TODAY()-Таблица1[[#This Row],[Дата регистрации клента]])/30 -> 42.5 | S27: =VLOOKUP(Таблица1[[#This Row],[id клиента]],Таблица8[[id клиента]:[Страна]],7,0) -> Украина
A28: 27 | B28: 415 | C28: 311 | D28: 5 | E28: 1555 | F28: 45099 | G28: Метро | H28: 24 | I28: =VLOOKUP(продажи!$B28,товар!$A$1:$C$433,2) -> Чипсы | J28: =VLOOKUP(B28,товар!$A$1:$C$433,3) -> Pringles | K28: =AVERAGEIF(продажи!$I$2:$I$1001,продажи!$I$2:$I$1001,продажи!$C$2:$C$1001) -> 273.72549 | L28: =продажи!$C28/продажи!$K28-1 -> 0.13617479 | M28: =SUMIFS($C$2:$C$1001,$I$2:$I$1001,I28,$J$2:$J$1001,J28) -> 5885 | N28: =Таблица1[[#This Row],[цена за шт в рублях]]/Таблица1[[#This Row],[средняя стоимость в категории по поставщику.]]-1 -> -0.94715378 | O28: =VLOOKUP(Таблица1[[#This Row],[id клиента]],клиенты!$A$2:$E$435,5,0) -> 44609 | P28: =Таблица1[[#This Row],[дата создания чека]]-Таблица1[[#This Row],[Дата регистрации клента]] -> 490 | Q28: =TODAY() -> 46059 | R28: =(TODAY()-Таблица1[[#This Row],[Дата регистрации клента]])/30 -> 48.333333 | S28: =VLOOKUP(Таблица1[[#This Row],[id клиента]],Таблица8[[id клиента]:[Страна]],7,0) -> Узбекистан
A29: 28 | B29: 176 | C29: 220 | D29: 1 | E29: 220 | F29: 45368 | G29: Бристоль | H29: 112 | I29: =VLOOKUP(продажи!$B29,товар!$A$1:$C$433,2) -> Сахар | J29: =VLOOKUP(B29,товар!$A$1:$C$433,3) -> Продимекс | K29: =AVERAGEIF(продажи!$I$2:$I$1001,продажи!$I$2:$I$1001,продажи!$C$2:$C$1001) -> 254.58333 | L29: =продажи!$C29/продажи!$K29-1 -> -0.13584288 | M29: =SUMIFS($C$2:$C$1001,$I$2:$I$1001,I29,$J$2:$J$1001,J29) -> 5172 | N29: =Таблица1[[#This Row],[цена за шт в рублях]]/Таблица1[[#This Row],[средняя стоимость в категории по поставщику.]]-1 -> -0.95746326 | O29: =VLOOKUP(Таблица1[[#This Row],[id клиента]],клиенты!$A$2:$E$435,5,0) -> 44652 | P29: =Таблица1[[#This Row],[дата создания чека]]-Таблица1[[#This Row],[Дата регистрации клента]] -> 716 | Q29: =TODAY() -> 46059 | R29: =(TODAY()-Таблица1[[#This Row],[Дата регистрации клента]])/30 -> 46.9 | S29: =VLOOKUP(Таблица1[[#This Row],[id клиента]],Таблица8[[id клиента]:[Страна]],7,0) -> Россия
A30: 845 | B30: 474 | C30: 405 | D30: 2 | E30: 810 | F30: 45390 | G30: Перекресток | H30: 18 | I30: =VLOOKUP(продажи!$B846,товар!$A$1:$C$433,2) -> Молоко | J30: =VLOOKUP(B30,товар!$A$1:$C$433,3) -> Простоквашино | K30: =AVERAGEIF(продажи!$I$2:$I$1001,продажи!$I$2:$I$1001,продажи!$C$2:$C$1001) -> 294.95238 | L30: =продажи!$C846/продажи!$K846-1 -> 0.48837585 | M30: =SUMIFS($C$2:$C$1001,$I$2:$I$1001,I30,$J$2:$J$1001,J30) -> 3507 | N30: =Таблица1[[#This Row],[цена за шт в рублях]]/Таблица1[[#This Row],[средняя стоимость в категории по поставщику.]]-1 -> -0.88451668 | O30: =VLOOKUP(Таблица1[[#This Row],[id клиента]],клиенты!$A$2:$E$435,5,0) -> 44578 | P30: =Таблица1[[#This Row],[дата создания чека]]-Таблица1[[#This Row],[Дата регистрации клента]] -> 812 | Q30: =TODAY() -> 46059 | R30: =(TODAY()-Таблица1[[#This Row],[Дата регистрации клента]])/30 -> 49.366667 | S30: =VLOOKUP(Таблица1[[#This Row],[id клиента]],Таблица8[[id клиента]:[Страна]],7,0) -> Украина
A31: 30 | B31: 399 | C31: 190 | D31: 1 | E31: 190 | F31: 45414 | G31: Городской Супермаркет | H31: 131 | I31: =VLOOKUP(продажи!$B31,товар!$A$1:$C$433,2) -> Хлеб | J31: =VLOOKUP(B31,товар!$A$1:$C$433,3) -> Хлебный Дом | K31: =AVERAGEIF(продажи!$I$2:$I$1001,продажи!$I$2:$I$1001,продажи!$C$2:$C$1001) -> 300.31818 | L31: =продажи!$C31/продажи!$K31-1 -> -0.36733767 | M31: =SUMIFS($C$2:$C$1001,$I$2:$I$1001,I31,$J$2:$J$1001,J31) -> 4226 | N31: =Таблица1[[#This Row],[цена за шт в рублях]]/Таблица1[[#This Row],[средняя стоимость в категории по поставщику.]]-1 -> -0.95504023 | O31: =VLOOKUP(Таблица1[[#This Row],[id клиента]],клиенты!$A$2:$E$435,5,0) -> 44693 | P31: =Таблица1[[#This Row],[дата создания чека]]-Таблица1[[#This Row],[Дата регистрации клента]] -> 721 | Q31: =TODAY() -> 46059 | R31: =(TODAY()-Таблица1[[#This Row],[Дата регистрации клента]])/30 -> 45.533333 | S31: =VLOOKUP(Таблица1[[#This Row],[id клиента]],Таблица8[[id клиента]:[Страна]],7,0) -> Россия
A32: 31 | B32: 382 | C32: 198 | D32: 5 | E32: 990 | F32: 45125 | G32: Билла | H32: 160 | I32: =VLOOKUP(продажи!$B32,товар!$A$1:$C$433,2) -> Овощи | J32: =VLOOKUP(B32,товар!$A$1:$C$433,3) -> Овощной ряд | K32: =AVERAGEIF(продажи!$I$2:$I$1001,продажи!$I$2:$I$1001,продажи!$C$2:$C$1001) -> 250.4878 | L32: =продажи!$C32/продажи!$K32-1 -> -0.20954236 | M32: =SUMIFS($C$2:$C$1001,$I$2:$I$1001,I32,$J$2:$J$1001,J32) -> 5165 | N32: =Таблица1[[#This Row],[цена за шт в рублях]]/Таблица1[[#This Row],[средняя стоимость в категории по поставщику.]]-1 -> -0.96166505 | O32: =VLOOKUP(Таблица1[[#This Row],[id клиента]],клиенты!$A$2:$E$435,5,0) -> 44649 | P32: =Таблица1[[#This Row],[дата создания чека]]-Таблица1[[#This Row],[Дата регистрации клента]] -> 476 | Q32: =TODAY() -> 46059 | R32: =(TODAY()-Таблица1[[#This Row],[Дата регистрации клента]])/30 -> 47 | S32: =VLOOKUP(Таблица1[[#This Row],[id клиента]],Таблица8[[id клиента]:[Страна]],7,0) -> Узбекистан
A33: 32 | B33: 103 | C33: 254 | D33: 3 | E33: 762 | F33: 45352 | G33: Пятерочка | H33: 408 | I33: =VLOOKUP(продажи!$B33,товар!$A$1:$C$433,2) -> Рыба | J33: =VLOOKUP(B33,товар!$A$1:$C$433,3) -> Санта Бремор | K33: =AVERAGEIF(продажи!$I$2:$I$1001,продажи!$I$2:$I$1001,продажи!$C$2:$C$1001) -> 258.51282 | L33: =продажи!$C33/продажи!$K33-1 -> -0.017456854 | M33: =SUMIFS($C$2:$C$1001,$I$2:$I$1001,I33,$J$2:$J$1001,J33) -> 2164 | N33: =Таблица1[[#This Row],[цена за шт в рублях]]/Таблица1[[#This Row],[средняя стоимость в категории по поставщику.]]-1 -> -0.88262477 | O33: =VLOOKUP(Таблица1[[#This Row],[id клиента]],клиенты!$A$2:$E$435,5,0) -> 44857 | P33: =Таблица1[[#This Row],[дата создания чека]]-Таблица1[[#This Row],[Дата регистрации клента]] -> 495 | Q33: =TODAY() -> 46059 | R33: =(TODAY()-Таблица1[[#This Row],[Дата регистрации клента]])/30 -> 40.066667 | S33: =VLOOKUP(Таблица1[[#This Row],[id клиента]],Таблица8[[id клиента]:[Страна]],7,0) -> Россия
A34: 33 | B34: 104 | C34: 351 | D34: 1 | E34: 351 | F34: 44997 | G34: Билла | H34: 324 | I34: =VLOOKUP(продажи!$B34,товар!$A$1:$C$433,2) -> Йогурт | J34: =VLOOKUP(B34,товар!$A$1:$C$433,3) -> Ростагроэкспорт | K34: =AVERAGEIF(продажи!$I$2:$I$1001,продажи!$I$2:$I$1001,продажи!$C$2:$C$1001) -> 263.25424 | L34: =продажи!$C34/продажи!$K34-1 -> 0.33331187 | M34: =SUMIFS($C$2:$C$1001,$I$2:$I$1001,I34,$J$2:$J$1001,J34) -> 5929 | N34: =Таблица1[[#This Row],[цена за шт в рублях]]/Таблица1[[#This Row],[средняя стоимость в категории по поставщику.]]-1 -> -0.94079946 | O34: =VLOOKUP(Таблица1[[#This Row],[id клиента]],клиенты!$A$2:$E$435,5,0) -> 44761 | P34: =Таблица1[[#This Row],[дата создания чека]]-Таблица1[[#This Row],[Дата регистрации клента]] -> 236 | Q34: =TODAY() -> 46059 | R34: =(TODAY()-Таблица1[[#This Row],[Дата регистрации клента]])/30 -> 43.266667 | S34: =VLOOKUP(Таблица1[[#This Row],[id клиента]],Таблица8[[id клиента]:[Страна]],7,0) -> Узбекистан
A35: 34 | B35: 213 | C35: 387 | D35: 1 | E35: 387 | F35: 45267 | G35: Карусель | H35: 310 | I35: =VLOOKUP(продажи!$B35,товар!$A$1:$C$433,2) -> Сахар | J35: =VLOOKUP(B35,товар!$A$1:$C$433,3) -> Продимекс | K35: =AVERAGEIF(продажи!$I$2:$I$1001,продажи!$I$2:$I$1001,продажи!$C$2:$C$1001) -> 254.58333 | L35: =продажи!$C35/продажи!$K35-1 -> 0.52013093 | M35: =SUMIFS($C$2:$C$1001,$I$2:$I$1001,I35,$J$2:$J$1001,J35) -> 5172 | N35: =Таблица1[[#This Row],[цена за шт в рублях]]/Таблица1[[#This Row],[средняя стоимость в категории по поставщику.]]-1 -> -0.92517401 | O35: =VLOOKUP(Таблица1[[#This Row],[id клиента]],клиенты!$A$2:$E$435,5,0) -> 44807 | P35: =Таблица1[[#This Row],[дата создания чека]]-Таблица1[[#This Row],[Дата регистрации клента]] -> 460 | Q35: =TODAY() -> 46059 | R35: =(TODAY()-Таблица1[[#This Row],[Дата регистрации клента]])/30 -> 41.733333 | S35: =VLOOKUP(Таблица1[[#This Row],[id клиента]],Таблица8[[id клиента]:[Страна]],7,0) -> Таджикистан
A36: 35 | B36: 157 | C36: 55 | D36: 2 | E36: 110 | F36: 45381 | G36: Городской Супермаркет | H36: 179 | I36: =VLOOKUP(продажи!$B36,товар!$A$1:$C$433,2) -> Сыр | J36: =VLOOKUP(B36,товар!$A$1:$C$433,3) -> President | K36: =AVERAGEIF(продажи!$I$2:$I$1001,продажи!$I$2:$I$1001,продажи!$C$2:$C$1001) -> 261.03226 | L36: =продажи!$C36/продажи!$K36-1 -> -0.78929807 | M36: =SUMIFS($C$2:$C$1001,$I$2:$I$1001,I36,$J$2:$J$1001,J36) -> 3935 | N36: =Таблица1[[#This Row],[цена за шт в рублях]]/Таблица1[[#This Row],[средняя стоимость в категории по поставщику.]]-1 -> -0.98602287 | O36: =VLOOKUP(Таблица1[[#This Row],[id клиента]],клиенты!$A$2:$E$435,5,0) -> 44833 | P36: =Таблица1[[#This Row],[дата создания чека]]-Таблица1[[#This Row],[Дата регистрации клента]] -> 548 | Q36: =TODAY() -> 46059 | R36: =(TODAY()-Таблица1[[#This Row],[Дата регистрации клента]])/30 -> 40.866667 | S36: =VLOOKUP(Таблица1[[#This Row],[id клиента]],Таблица8[[id клиента]:[Страна]],7,0) -> Россия
A37: 36 | B37: 237 | C37: 336 | D37: 1 | E37: 336 | F37: 44971 | G37: Гиперглобус | H37: 64 | I37: =VLOOKUP(продажи!$B37,товар!$A$1:$C$433,2) -> Конфеты | J37: =VLOOKUP(B37,товар!$A$1:$C$433,3) -> Рот Фронт | K37: =AVERAGEIF(продажи!$I$2:$I$1001,продажи!$I$2:$I$1001,продажи!$C$2:$C$1001) -> 267.85484 | L37: =продажи!$C37/продажи!$K37-1 -> 0.25441079 | M37: =SUMIFS($C$2:$C$1001,$I$2:$I$1001,I37,$J$2:$J$1001,J37) -> 6053 | N37: =Таблица1[[#This Row],[цена за шт в рублях]]/Таблица1[[#This Row],[средняя стоимость в категории по поставщику.]]-1 -> -0.94449034 | O37: =VLOOKUP(Таблица1[[#This Row],[id клиента]],клиенты!$A$2:$E$435,5,0) -> 44707 | P37: =Таблица1[[#This Row],[дата создания чека]]-Таблица1[[#This Row],[Дата регистрации клента]] -> 264 | Q37: =TODAY() -> 46059 | R37: =(TODAY()-Таблица1[[#This Row],[Дата регистрации клента]])/30 -> 45.066667 | S37: =VLOOKUP(Таблица1[[#This Row],[id клиента]],Таблица8[[id клиента]:[Страна]],7,0) -> Узбекистан
A38: 37 | B38: 8 | C38: 480 | D38: 4 | E38: 1920 | F38: 44947 | G38: О'кей | H38: 318 | I38: =VLOOKUP(продажи!$B38,товар!$A$1:$C$433,2) -> Макароны | J38: =VLOOKUP(B38,товар!$A$1:$C$433,3) -> Паста Зара | K38: =AVERAGEIF(продажи!$I$2:$I$1001,продажи!$I$2:$I$1001,продажи!$C$2:$C$1001) -> 265.47674 | L38: =продажи!$C38/продажи!$K38-1 -> 0.80806798 | M38: =SUMIFS($C$2:$C$1001,$I$2:$I$1001,I38,$J$2:$J$1001,J38) -> 10237 | N38: =Таблица1[[#This Row],[цена за шт в рублях]]/Таблица1[[#This Row],[средняя стоимость в категории по поставщику.]]-1 -> -0.95311126 | O38: =VLOOKUP(Таблица1[[#This Row],[id клиента]],клиенты!$A$2:$E$435,5,0) -> 44892 | P38: =Таблица1[[#This Row],[дата создания чека]]-Таблица1[[#This Row],[Дата регистрации клента]] -> 55 | Q38: =TODAY() -> 46059 | R38: =(TODAY()-Таблица1[[#This Row],[Дата регистрации клента]])/30 -> 38.9 | S38: =VLOOKUP(Таблица1[[#This Row],[id клиента]],Таблица8[[id клиента]:[Страна]],7,0) -> Узбекистан
A39: 38 | B39: 65 | C39: 214 | D39: 3 | E39: 642 | F39: 45129 | G39: Бристоль | H39: 239 | I39: =VLOOKUP(продажи!$B39,товар!$A$1:$C$433,2) -> Хлеб | J39: =VLOOKUP(B39,товар!$A$1:$C$433,3) -> Хлебный Дом | K39: =AVERAGEIF(продажи!$I$2:$I$1001,продажи!$I$2:$I$1001,продажи!$C$2:$C$1001) -> 300.31818 | L39: =продажи!$C39/продажи!$K39-1 -> -0.28742243 | M39: =SUMIFS($C$2:$C$1001,$I$2:$I$1001,I39,$J$2:$J$1001,J39) -> 4226 | N39: =Таблица1[[#This Row],[цена за шт в рублях]]/Таблица1[[#This Row],[средняя стоимость в категории по поставщику.]]-1 -> -0.9493611 | O39: =VLOOKUP(Таблица1[[#This Row],[id клиента]],клиенты!$A$2:$E$435,5,0) -> 44767 | P39: =Таблица1[[#This Row],[дата создания чека]]-Таблица1[[#This Row],[Дата регистрации клента]] -> 362 | Q39: =TODAY() -> 46059 | R39: =(TODAY()-Таблица1[[#This Row],[Дата регистрации клента]])/30 -> 43.066667 | S39: =VLOOKUP(Таблица1[[#This Row],[id клиента]],Таблица8[[id клиента]:[Страна]],7,0) -> Узбекистан
A40: 39 | B40: 45 | C40: 60 | D40: 2 | E40: 120 | F40: 45406 | G40: Ароматный Мир | H40: 194 | I40: =VLOOKUP(продажи!$B40,товар!$A$1:$C$433,2) -> Сок | J40: =VLOOKUP(B40,товар!$A$1:$C$433,3) -> Добрый | K40: =AVERAGEIF(продажи!$I$2:$I$1001,продажи!$I$2:$I$1001,продажи!$C$2:$C$1001) -> 268.60345 | L40: =продажи!$C40/продажи!$K40-1 -> -0.77662238 | M40: =SUMIFS($C$2:$C$1001,$I$2:$I$1001,I40,$J$2:$J$1001,J40) -> 2671 | N40: =Таблица1[[#This Row],[цена за шт в рублях]]/Таблица1[[#This Row],[средняя стоимость в категории по поставщику.]]-1 -> -0.9775365 | O40: =VLOOKUP(Таблица1[[#This Row],[id клиента]],клиенты!$A$2:$E$435,5,0) -> 44924 | P40: =Таблица1[[#This Row],[дата создания чека]]-Таблица1[[#This Row],[Дата регистрации клента]] -> 482 | Q40: =TODAY() -> 46059 | R40: =(TODAY()-Таблица1[[#This Row],[Дата регистрации клента]])/30 -> 37.833333 | S40: =VLOOKUP(Таблица1[[#This Row],[id клиента]],Таблица8[[id клиента]:[Страна]],7,0) -> Россия
A41: 40 | B41: 36 | C41: 414 | D41: 3 | E41: 1242 | F41: 45117 | G41: Мираторг | H41: 267 | I41: =VLOOKUP(продажи!$B41,товар!$A$1:$C$433,2) -> Макароны | J41: =VLOOKUP(B41,товар!$A$1:$C$433,3) -> Роллтон | K41: =AVERAGEIF(продажи!$I$2:$I$1001,продажи!$I$2:$I$1001,продажи!$C$2:$C$1001) -> 265.47674 | L41: =продажи!$C41/продажи!$K41-1 -> 0.55945863 | M41: =SUMIFS($C$2:$C$1001,$I$2:$I$1001,I41,$J$2:$J$1001,J41) -> 2120 | N41: =Таблица1[[#This Row],[цена за шт в рублях]]/Таблица1[[#This Row],[средняя стоимость в категории по поставщику.]]-1 -> -0.80471698 | O41: =VLOOKUP(Таблица1[[#This Row],[id клиента]],клиенты!$A$2:$E$435,5,0) -> 44910 | P41: =Таблица1[[#This Row],[дата создания чека]]-Таблица1[[#This Row],[Дата регистрации клента]] -> 207 | Q41: =TODAY() -> 46059 | R41: =(TODAY()-Таблица1[[#This Row],[Дата регистрации клента]])/30 -> 38.3 | S41: =VLOOKUP(Таблица1[[#This Row],[id клиента]],Таблица8[[id клиента]:[Страна]],7,0) -> Россия
A42: 41 | B42: 443 | C42: 62 | D42: 3 | E42: 186 | F42: 45194 | G42: Спар | H42: 334 | I42: =VLOOKUP(продажи!$B42,товар!$A$1:$C$433,2) -> Кофе | J42: =VLOOKUP(B42,товар!$A$1:$C$433,3) -> Jacobs | K42: =AVERAGEIF(продажи!$I$2:$I$1001,продажи!$I$2:$I$1001,продажи!$C$2:$C$1001) -> 249.02381 | L42: =продажи!$C42/продажи!$K42-1 -> -0.75102782 | M42: =SUMIFS($C$2:$C$1001,$I$2:$I$1001,I42,$J$2:$J$1001,J42) -> 5248 | N42: =Таблица1[[#This Row],[цена за шт в рублях]]/Таблица1[[#This Row],[средняя стоимость в категории по поставщику.]]-1 -> -0.98818598 | O42: =VLOOKUP(Таблица1[[#This Row],[id клиента]],клиенты!$A$2:$E$435,5,0) -> 44881 | P42: =Таблица1[[#This Row],[дата создания чека]]-Таблица1[[#This Row],[Дата регистрации клента]] -> 313 | Q42: =TODAY() -> 46059 | R42: =(TODAY()-Таблица1[[#This Row],[Дата регистрации клента]])/30 -> 39.266667 | S42: =VLOOKUP(Таблица1[[#This Row],[id клиента]],Таблица8[[id клиента]:[Страна]],7,0) -> Украина
... A82: 81 | B82: 116 | C82: 120 | D82: 2 | E82: 240 | F82: 45326 | G82: Ашан | H82: 332 | I82: =VLOOKUP(продажи!$B82,товар!$A$1:$C$433,2) -> Соль | J82: =VLOOKUP(B82,товар!$A$1:$C$433,3) -> Экстра | K82: =AVERAGEIF(продажи!$I$2:$I$1001,продажи!$I$2:$I$1001,продажи!$C$2:$C$1001) -> 264.86792 | L82: =продажи!$C82/продажи!$K82-1 -> -0.54694401 | M82: =SUMIFS($C$2:$C$1001,$I$2:$I$1001,I82,$J$2:$J$1001,J82) -> 4171 | N82: =Таблица1[[#This Row],[цена за шт в рублях]]/Таблица1[[#This Row],[средняя стоимость в категории по поставщику.]]-1 -> -0.97122992 | O82: =VLOOKUP(Таблица1[[#This Row],[id клиента]],клиенты!$A$2:$E$435,5,0) -> 44858 | P82: =Таблица1[[#This Row],[дата создания чека]]-Таблица1[[#This Row],[Дата регистрации клента]] -> 468 | Q82: =TODAY() -> 46059 | R82: =(TODAY()-Таблица1[[#This Row],[Дата регистрации клента]])/30 -> 40.033333 | S82: =VLOOKUP(Таблица1[[#This Row],[id клиента]],Таблица8[[id клиента]:[Страна]],7,0) -> Узбекистан
A83: 150 | B83: 232 | C83: 109 | D83: 4 | E83: 436 | F83: 45387 | G83: Билла | H83: 407 | I83: =VLOOKUP(продажи!$B151,товар!$A$1:$C$433,2) -> Молоко | J83: =VLOOKUP(B83,товар!$A$1:$C$433,3) -> Простоквашино | K83: =AVERAGEIF(продажи!$I$2:$I$1001,продажи!$I$2:$I$1001,продажи!$C$2:$C$1001) -> 294.95238 | L83: =продажи!$C151/продажи!$K151-1 -> -0.1456248 | M83: =SUMIFS($C$2:$C$1001,$I$2:$I$1001,I83,$J$2:$J$1001,J83) -> 3507 | N83: =Таблица1[[#This Row],[цена за шт в рублях]]/Таблица1[[#This Row],[средняя стоимость в категории по поставщику.]]-1 -> -0.9689193 | O83: =VLOOKUP(Таблица1[[#This Row],[id клиента]],клиенты!$A$2:$E$435,5,0) -> 44621 | P83: =Таблица1[[#This Row],[дата создания чека]]-Таблица1[[#This Row],[Дата регистрации клента]] -> 766 | Q83: =TODAY() -> 46059 | R83: =(TODAY()-Таблица1[[#This Row],[Дата регистрации клента]])/30 -> 47.933333 | S83: =VLOOKUP(Таблица1[[#This Row],[id клиента]],Таблица8[[id клиента]:[Страна]],7,0) -> Беларусь
A84: 83 | B84: 345 | C84: 267 | D84: 5 | E84: 1335 | F84: 45004 | G84: Дикси | H84: 287 | I84: =VLOOKUP(продажи!$B84,товар!$A$1:$C$433,2) -> Конфеты | J84: =VLOOKUP(B84,товар!$A$1:$C$433,3) -> Рот Фронт | K84: =AVERAGEIF(продажи!$I$2:$I$1001,продажи!$I$2:$I$1001,продажи!$C$2:$C$1001) -> 267.85484 | L84: =продажи!$C84/продажи!$K84-1 -> -0.0031914253 | M84: =SUMIFS($C$2:$C$1001,$I$2:$I$1001,I84,$J$2:$J$1001,J84) -> 6053 | N84: =Таблица1[[#This Row],[цена за шт в рублях]]/Таблица1[[#This Row],[средняя стоимость в категории по поставщику.]]-1 -> -0.95588964 | O84: =VLOOKUP(Таблица1[[#This Row],[id клиента]],клиенты!$A$2:$E$435,5,0) -> 44608 | P84: =Таблица1[[#This Row],[дата создания чека]]-Таблица1[[#This Row],[Дата регистрации клента]] -> 396 | Q84: =TODAY() -> 46059 | R84: =(TODAY()-Таблица1[[#This Row],[Дата регистрации клента]])/30 -> 48.366667 | S84: =VLOOKUP(Таблица1[[#This Row],[id клиента]],Таблица8[[id клиента]:[Страна]],7,0) -> Россия
A85: 84 | B85: 281 | C85: 371 | D85: 1 | E85: 371 | F85: 44993 | G85: О'кей | H85: 11 | I85: =VLOOKUP(продажи!$B85,товар!$A$1:$C$433,2) -> Чай | J85: =VLOOKUP(B85,товар!$A$1:$C$433,3) -> Lipton | K85: =AVERAGEIF(продажи!$I$2:$I$1001,продажи!$I$2:$I$1001,продажи!$C$2:$C$1001) -> 271.18182 | L85: =продажи!$C85/продажи!$K85-1 -> 0.36808582 | M85: =SUMIFS($C$2:$C$1001,$I$2:$I$1001,I85,$J$2:$J$1001,J85) -> 4943 | N85: =Таблица1[[#This Row],[цена за шт в рублях]]/Таблица1[[#This Row],[средняя стоимость в категории по поставщику.]]-1 -> -0.92494437 | O85: =VLOOKUP(Таблица1[[#This Row],[id клиента]],клиенты!$A$2:$E$435,5,0) -> 44690 | P85: =Таблица1[[#This Row],[дата создания чека]]-Таблица1[[#This Row],[Дата регистрации клента]] -> 303 | Q85: =TODAY() -> 46059 | R85: =(TODAY()-Таблица1[[#This Row],[Дата регистрации клента]])/30 -> 45.633333 | S85: =VLOOKUP(Таблица1[[#This Row],[id клиента]],Таблица8[[id клиента]:[Страна]],7,0) -> Таджикистан
A86: 85 | B86: 276 | C86: 295 | D86: 1 | E86: 295 | F86: 45272 | G86: Гиперглобус | H86: 458 | I86: =VLOOKUP(продажи!$B86,товар!$A$1:$C$433,2) -> Колбаса | J86: =VLOOKUP(B86,товар!$A$1:$C$433,3) -> Дымов | K86: =AVERAGEIF(продажи!$I$2:$I$1001,продажи!$I$2:$I$1001,продажи!$C$2:$C$1001) -> 286.92308 | L86: =продажи!$C86/продажи!$K86-1 -> 0.028150134 | M86: =SUMIFS($C$2:$C$1001,$I$2:$I$1001,I86,$J$2:$J$1001,J86) -> 2814 | N86: =Таблица1[[#This Row],[цена за шт в рублях]]/Таблица1[[#This Row],[средняя стоимость в категории по поставщику.]]-1 -> -0.89516702 | O86: =VLOOKUP(Таблица1[[#This Row],[id клиента]],клиенты!$A$2:$E$435,5,0) -> 44694 | P86: =Таблица1[[#This Row],[дата создания чека]]-Таблица1[[#This Row],[Дата регистрации клента]] -> 578 | Q86: =TODAY() -> 46059 | R86: =(TODAY()-Таблица1[[#This Row],[Дата регистрации клента]])/30 -> 45.5 | S86: =VLOOKUP(Таблица1[[#This Row],[id клиента]],Таблица8[[id клиента]:[Страна]],7,0) -> Россия
A87: 86 | B87: 234 | C87: 75 | D87: 5 | E87: 375 | F87: 44939 | G87: Ароматный Мир | H87: 130 | I87: =VLOOKUP(продажи!$B87,товар!$A$1:$C$433,2) -> Чай | J87: =VLOOKUP(B87,товар!$A$1:$C$433,3) -> Greenfield | K87: =AVERAGEIF(продажи!$I$2:$I$1001,продажи!$I$2:$I$1001,продажи!$C$2:$C$1001) -> 271.18182 | L87: =продажи!$C87/продажи!$K87-1 -> -0.72343279 | M87: =SUMIFS($C$2:$C$1001,$I$2:$I$1001,I87,$J$2:$J$1001,J87) -> 6412 | N87: =Таблица1[[#This Row],[цена за шт в рублях]]/Таблица1[[#This Row],[средняя стоимость в категории по поставщику.]]-1 -> -0.98830318 | O87: =VLOOKUP(Таблица1[[#This Row],[id клиента]],клиенты!$A$2:$E$435,5,0) -> 44863 | P87: =Таблица1[[#This Row],[дата создания чека]]-Таблица1[[#This Row],[Дата регистрации клента]] -> 76 | Q87: =TODAY() -> 46059 | R87: =(TODAY()-Таблица1[[#This Row],[Дата регистрации клента]])/30 -> 39.866667 | S87: =VLOOKUP(Таблица1[[#This Row],[id клиента]],Таблица8[[id клиента]:[Страна]],7,0) -> Таджикистан
A88: 87 | B88: 319 | C88: 247 | D88: 2 | E88: 494 | F88: 45189 | G88: Бристоль | H88: 330 | I88: =VLOOKUP(продажи!$B88,товар!$A$1:$C$433,2) -> Йогурт | J88: =VLOOKUP(B88,товар!$A$1:$C$433,3) -> Эрманн | K88: =AVERAGEIF(продажи!$I$2:$I$1001,продажи!$I$2:$I$1001,продажи!$C$2:$C$1001) -> 263.25424 | L88: =продажи!$C88/продажи!$K88-1 -> -0.061743497 | M88: =SUMIFS($C$2:$C$1001,$I$2:$I$1001,I88,$J$2:$J$1001,J88) -> 4970 | N88: =Таблица1[[#This Row],[цена за шт в рублях]]/Таблица1[[#This Row],[средняя стоимость в категории по поставщику.]]-1 -> -0.95030181 | O88: =VLOOKUP(Таблица1[[#This Row],[id клиента]],клиенты!$A$2:$E$435,5,0) -> 44815 | P88: =Таблица1[[#This Row],[дата создания чека]]-Таблица1[[#This Row],[Дата регистрации клента]] -> 374 | Q88: =TODAY() -> 46059 | R88: =(TODAY()-Таблица1[[#This Row],[Дата регистрации клента]])/30 -> 41.466667 | S88: =VLOOKUP(Таблица1[[#This Row],[id клиента]],Таблица8[[id клиента]:[Страна]],7,0) -> Узбекистан
A89: 88 | B89: 375 | C89: 281 | D89: 2 | E89: 562 | F89: 45079 | G89: Гиперглобус | H89: 167 | I89: =VLOOKUP(продажи!$B89,товар!$A$1:$C$433,2) -> Макароны | J89: =VLOOKUP(B89,товар!$A$1:$C$433,3) -> Борилла | K89: =AVERAGEIF(продажи!$I$2:$I$1001,продажи!$I$2:$I$1001,продажи!$C$2:$C$1001) -> 265.47674 | L89: =продажи!$C89/продажи!$K89-1 -> 0.058473129 | M89: =SUMIFS($C$2:$C$1001,$I$2:$I$1001,I89,$J$2:$J$1001,J89) -> 6852 | N89: =Таблица1[[#This Row],[цена за шт в рублях]]/Таблица1[[#This Row],[средняя стоимость в категории по поставщику.]]-1 -> -0.95899008 | O89: =VLOOKUP(Таблица1[[#This Row],[id клиента]],клиенты!$A$2:$E$435,5,0) -> 44563 | P89: =Таблица1[[#This Row],[дата создания чека]]-Таблица1[[#This Row],[Дата регистрации клента]] -> 516 | Q89: =TODAY() -> 46059 | R89: =(TODAY()-Таблица1[[#This Row],[Дата регистрации клента]])/30 -> 49.866667 | S89: =VLOOKUP(Таблица1[[#This Row],[id клиента]],Таблица8[[id клиента]:[Страна]],7,0) -> Узбекистан
A90: 89 | B90: 443 | C90: 136 | D90: 2 | E90: 272 | F90: 44927 | G90: Седьмой Континент | H90: 140 | I90: =VLOOKUP(продажи!$B90,товар!$A$1:$C$433,2) -> Кофе | J90: =VLOOKUP(B90,товар!$A$1:$C$433,3) -> Jacobs | K90: =AVERAGEIF(продажи!$I$2:$I$1001,продажи!$I$2:$I$1001,продажи!$C$2:$C$1001) -> 249.02381 | L90: =продажи!$C90/продажи!$K90-1 -> -0.45386748 | M90: =SUMIFS($C$2:$C$1001,$I$2:$I$1001,I90,$J$2:$J$1001,J90) -> 5248 | N90: =Таблица1[[#This Row],[цена за шт в рублях]]/Таблица1[[#This Row],[средняя стоимость в категории по поставщику.]]-1 -> -0.97408537 | O90: =VLOOKUP(Таблица1[[#This Row],[id клиента]],клиенты!$A$2:$E$435,5,0) -> 44627 | P90: =Таблица1[[#This Row],[дата создания чека]]-Таблица1[[#This Row],[Дата регистрации клента]] -> 300 | Q90: =TODAY() -> 46059 | R90: =(TODAY()-Таблица1[[#This Row],[Дата регистрации клента]])/30 -> 47.733333 | S90: =VLOOKUP(Таблица1[[#This Row],[id клиента]],Таблица8[[id клиента]:[Страна]],7,0) -> Россия
...

Sheet товар
A1: id товара | B1: категория товара | C1: поставщик
A2: 1 | B2: Крупа | C2: Ярмарка
A3: 3 | B3: Крупа | C3: Ярмарка
A4: 4 | B4: Рис | C4: Белый Злат
A5: 5 | B5: Макароны | C5: Роллтон
A6: 6 | B6: Фрукты | C6: Фрукты-Ягоды
A7: 7 | B7: Сыр | C7: President
A8: 8 | B8: Макароны | C8: Паста Зара
A9: 9 | B9: Йогурт | C9: Чудо
A10: 10 | B10: Сок | C10: Фруктовый сад
A11: 11 | B11: Хлеб | C11: Русский Хлеб
A12: 12 | B12: Макароны | C12: Макфа
A13: 13 | B13: Макароны | C13: Паста Зара
... A433: 499 | B433: Печенье | C433: Посиделкино

Sheet География клиентов
A1: Названия строк | B1: Количество по полю id клиента
A2: Россия | B2: 146
A3: Узбекистан | B3: 85
A4: Украина | B4: 78
A5: Таджикистан | B5: 74
A6: Беларусь | B6: 51
A7: Общий итог | B7: 434
E17: Большинство клиентов из России, меньшинство из Беларси

Sheet Программа лояльности
A3: Названия строк | B3: Количество по полю Программа лояльности клиента
A4: да | B4: 215
A5: нет | B5: 219
A6: Общий итог | B6: 434

Sheet Имена
A3: Названия строк | B3: Количество по полю Имя
A4: (пусто)
A5: Август | B5: 5
A6: Алексей | B6: 5
A7: Аверьян | B7: 5
A8: Алина | B8: 5
A9: Алевтина | B9: 5
A10: Амос | B10: 5
A11: Амвросий | B11: 5
A12: Андрон | B12: 5
A13: Ангелина | B13: 5
A14: Анжелика | B14: 5
A15: Анжелика | B15: 5
A16: Анна | B16: 5
... A18: Анна | B18: 5
A19: Антонина | B19: 5 | G19: 70% имен использутся п 5 раз
A20: Антонина | B20: 5
A21: Арефий | B21: 5
A22: Артемьева | B22: 5
A23: Богдан | B23: 5
A24: Афанасьев | B24: 5
A25: Борислав | B25: 5
A26: Бажен | B26: 5
A27: Вадим | B27: 5
A28: Боян | B28: 5
A29: Викентий | B29: 5
A30: Вадим | B30: 5
A31: Геннадий | B31: 5
... A308: Алевтина | B308: 1

Sheet клиенты
A1: id клиента | B1: номер телефона клиента | C1: ФИО | D1: Программа лояльности клиента | E1: Дата регистрации клиента | F1: Код телефона | G1: Страна | H1: Столбец1 | I1: Имя | J1: Фамилия | K1: Отч | M1: 1 пробел | N1: Втор | O1: Длина | Q1: Имя | R1: Фамилия | S1: Отчество
A2: 249 | B2: +7 974-088-4889 | C2: Абрамов Адриан Фролович | D2: да | E2: 44781 | F2: =LEFT(B2,LEN(B2)-13) -> +7 | G2: =INDEX('коды стран'!$A$2:$A$7, MATCH(F2, 'коды стран'!$B$2:$B$7, 0)) -> Россия | H2: Россия | I2: =LEFT(Таблица8[[#This Row],[ФИО]],(M2-1)) -> Абрамов | J2: =MID(Таблица8[[#This Row],[ФИО]],M2,(N2-M2)) -> Адриан | K2: =RIGHT(Таблица8[[#This Row],[ФИО]],(O2-N2)) -> Фролович | M2: =FIND(" ",Таблица8[[#This Row],[ФИО]],2) -> 8 | N2: =FIND(" ",Таблица8[[#This Row],[ФИО]],(M2+1)) -> 15 | O2: =LEN(Таблица8[[#This Row],[ФИО]]) -> 23 | Q2: =MID(Таблица8[[#This Row],[ФИО]],M2,(N2-M2)) -> Адриан | R2: Абрамов | S2: Фролович
A3: 343 | B3: +380 606-168-8976 | C3: Абрамов Амвросий Богданович | D3: нет | E3: 44874 | F3: =LEFT(B3,LEN(B3)-13) -> +380 | G3: =INDEX('коды стран'!$A$2:$A$7, MATCH(F3, 'коды стран'!$B$2:$B$7, 0)) -> Украина | H3: Украина | I3: =LEFT(Таблица8[[#This Row],[ФИО]],(M3-1)) -> Абрамов | J3: =MID(Таблица8[[#This Row],[ФИО]],M3,(N3-M3)) -> Амвросий | K3: =RIGHT(Таблица8[[#This Row],[ФИО]],(O3-N3)) -> Богданович | M3: =FIND(" ",Таблица8[[#This Row],[ФИО]],2) -> 8 | N3: =FIND(" ",Таблица8[[#This Row],[ФИО]],(M3+1)) -> 17 | O3: =LEN(Таблица8[[#This Row],[ФИО]]) -> 27 | Q3: =MID(Таблица8[[#This Row],[ФИО]],M3,(N3-M3)) -> Амвросий | R3: Абрамов | S3: Богданович
A4: 34 | B4: +992 266-481-3942 | C4: Абрамова Евдокия Егоровна | D4: нет | E4: 44654 | F4: =LEFT(B4,LEN(B4)-13) -> +992 | G4: =INDEX('коды стран'!$A$2:$A$7, MATCH(F4, 'коды стран'!$B$2:$B$7, 0)) -> Таджикистан | H4: Таджикистан | I4: =LEFT(Таблица8[[#This Row],[ФИО]],(M4-1)) -> Абрамова | J4: =MID(Таблица8[[#This Row],[ФИО]],M4,(N4-M4)) -> Евдокия | K4: =RIGHT(Таблица8[[#This Row],[ФИО]],(O4-N4)) -> Егоровна | M4: =FIND(" ",Таблица8[[#This Row],[ФИО]],2) -> 9 | N4: =FIND(" ",Таблица8[[#This Row],[ФИО]],(M4+1)) -> 17 | O4: =LEN(Таблица8[[#This Row],[ФИО]]) -> 25 | Q4: =MID(Таблица8[[#This Row],[ФИО]],M4,(N4-M4)) -> Евдокия | R4: Абрамова | S4: Егоровна
A5: 365 | B5: +375 260-927-0999 | C5: Абрамова Елизавета Эдуардовна | D5: нет | E5: 44841 | F5: =LEFT(B5,LEN(B5)-13) -> +375 | G5: =INDEX('коды стран'!$A$2:$A$7, MATCH(F5, 'коды стран'!$B$2:$B$7, 0)) -> Беларусь | H5: Беларусь | I5: =LEFT(Таблица8[[#This Row],[ФИО]],(M5-1)) -> Абрамова | J5: =MID(Таблица8[[#This Row],[ФИО]],M5,(N5-M5)) -> Елизавета | K5: =RIGHT(Таблица8[[#This Row],[ФИО]],(O5-N5)) -> Эдуардовна | M5: =FIND(" ",Таблица8[[#This Row],[ФИО]],2) -> 9 | N5: =FIND(" ",Таблица8[[#This Row],[ФИО]],(M5+1)) -> 19 | O5: =LEN(Таблица8[[#This Row],[ФИО]]) -> 29 | Q5: =MID(Таблица8[[#This Row],[ФИО]],M5,(N5-M5)) -> Елизавета | R5: Абрамова | S5: Эдуардовна
A6: 413 | B6: +7 063-931-5918 | C6: Август Вячеславович Брагин | D6: нет | E6: 44699 | F6: =LEFT(B6,LEN(B6)-13) -> +7 | G6: =INDEX('коды стран'!$A$2:$A$7, MATCH(F6, 'коды стран'!$B$2:$B$7, 0)) -> Россия | H6: Россия | I6: =LEFT(Таблица8[[#This Row],[ФИО]],(M6-1)) -> Август | J6: =MID(Таблица8[[#This Row],[ФИО]],M6,(N6-M6)) -> Вячеславович | K6: =RIGHT(Таблица8[[#This Row],[ФИО]],(O6-N6)) -> Брагин | M6: =FIND(" ",Таблица8[[#This Row],[ФИО]],2) -> 7 | N6: =FIND(" ",Таблица8[[#This Row],[ФИО]],(M6+1)) -> 20 | O6: =LEN(Таблица8[[#This Row],[ФИО]]) -> 26 | Q6: =LEFT(Таблица8[[#This Row],[ФИО]],(M6-1)) -> Август | R6: Брагин | S6: Вячеславович
A7: 93 | B7: +380 686-730-6702 | C7: Авдеев Олимпий Жанович | D7: нет | E7: 44905 | F7: =LEFT(B7,LEN(B7)-13) -> +380 | G7: =INDEX('коды стран'!$A$2:$A$7, MATCH(F7, 'коды стран'!$B$2:$B$7, 0)) -> Украина | H7: Украина | I7: =LEFT(Таблица8[[#This Row],[ФИО]],(M7-1)) -> Авдеев | J7: =MID(Таблица8[[#This Row],[ФИО]],M7,(N7-M7)) -> Олимпий | K7: =RIGHT(Таблица8[[#This Row],[ФИО]],(O7-N7)) -> Жанович | M7: =FIND(" ",Таблица8[[#This Row],[ФИО]],2) -> 7 | N7: =FIND(" ",Таблица8[[#This Row],[ФИО]],(M7+1)) -> 15 | O7: =LEN(Таблица8[[#This Row],[ФИО]]) -> 22 | Q7: =MID(Таблица8[[#This Row],[ФИО]],M7,(N7-M7)) -> Олимпий | R7: Авдеев | S7: Жанович
A8: 349 | B8: +7 048-020-5515 | C8: Авдеев Филипп Елисеевич | D8: нет | E8: 44673 | F8: =LEFT(B8,LEN(B8)-13) -> +7 | G8: =INDEX('коды стран'!$A$2:$A$7, MATCH(F8, 'коды стран'!$B$2:$B$7, 0)) -> Россия | H8: Россия | I8: =LEFT(Таблица8[[#This Row],[ФИО]],(M8-1)) -> Авдеев | J8: =MID(Таблица8[[#This Row],[ФИО]],M8,(N8-M8)) -> Филипп | K8: =RIGHT(Таблица8[[#This Row],[ФИО]],(O8-N8)) -> Елисеевич | M8: =FIND(" ",Таблица8[[#This Row],[ФИО]],2) -> 7 | N8: =FIND(" ",Таблица8[[#This Row],[ФИО]],(M8+1)) -> 14 | O8: =LEN(Таблица8[[#This Row],[ФИО]]) -> 23 | Q8: =MID(Таблица8[[#This Row],[ФИО]],M8,(N8-M8)) -> Филипп | R8: Авдеев | S8: Елисеевич
A9: 362 | B9: +7 739-924-9444 | C9: Авдей Брониславович Владимиров | D9: нет | E9: 44916 | F9: =LEFT(B9,LEN(B9)-13) -> +7 | G9: =INDEX('коды стран'!$A$2:$A$7, MATCH(F9, 'коды стран'!$B$2:$B$7, 0)) -> Россия | H9: Россия | I9: =LEFT(Таблица8[[#This Row],[ФИО]],(M9-1)) -> Авдей | J9: =MID(Таблица8[[#This Row],[ФИО]],M9,(N9-M9)) -> Брониславович | K9: =RIGHT(Таблица8[[#This Row],[ФИО]],(O9-N9)) -> Владимиров | M9: =FIND(" ",Таблица8[[#This Row],[ФИО]],2) -> 6 | N9: =FIND(" ",Таблица8[[#This Row],[ФИО]],(M9+1)) -> 20 | O9: =LEN(Таблица8[[#This Row],[ФИО]]) -> 30 | Q9: =LEFT(Таблица8[[#This Row],[ФИО]],(M9-1)) -> Авдей | R9: Владимиров | S9: Брониславович
A10: 389 | B10: +7 524-093-8464 | C10: Автоном Терентьевич Филиппов | D10: да | E10: 44876 | F10: =LEFT(B10,LEN(B10)-13) -> +7 | G10: =INDEX('коды стран'!$A$2:$A$7, MATCH(F10, 'коды стран'!$B$2:$B$7, 0)) -> Россия | H10: Россия | I10: =LEFT(Таблица8[[#This Row],[ФИО]],(M10-1)) -> Автоном | J10: =MID(Таблица8[[#This Row],[ФИО]],M10,(N10-M10)) -> Терентьевич | K10: =RIGHT(Таблица8[[#This Row],[ФИО]],(O10-N10)) -> Филиппов | M10: =FIND(" ",Таблица8[[#This Row],[ФИО]],2) -> 8 | N10: =FIND(" ",Таблица8[[#This Row],[ФИО]],(M10+1)) -> 20 | O10: =LEN(Таблица8[[#This Row],[ФИО]]) -> 28 | Q10: =LEFT(Таблица8[[#This Row],[ФИО]],(M10-1)) -> Автоном | R10: Филиппов | S10: Терентьевич
A11: 226 | B11: +7 685-361-2926 | C11: Агап Валерьевич Логинов | D11: да | E11: 44702 | F11: =LEFT(B11,LEN(B11)-13) -> +7 | G11: =INDEX('коды стран'!$A$2:$A$7, MATCH(F11, 'коды стран'!$B$2:$B$7, 0)) -> Россия | H11: Россия | I11: =LEFT(Таблица8[[#This Row],[ФИО]],(M11-1)) -> Агап | J11: =MID(Таблица8[[#This Row],[ФИО]],M11,(N11-M11)) -> Валерьевич | K11: =RIGHT(Таблица8[[#This Row],[ФИО]],(O11-N11)) -> Логинов | M11: =FIND(" ",Таблица8[[#This Row],[ФИО]],2) -> 5 | N11: =FIND(" ",Таблица8[[#This Row],[ФИО]],(M11+1)) -> 16 | O11: =LEN(Таблица8[[#This Row],[ФИО]]) -> 23 | Q11: =LEFT(Таблица8[[#This Row],[ФИО]],(M11-1)) -> Агап | R11: Логинов | S11: Валерьевич
A12: 142 | B12: +7 600-803-0627 | C12: Агата Геннадьевна Колесникова | D12: нет | E12: 44683 | F12: =LEFT(B12,LEN(B12)-13) -> +7 | G12: =INDEX('коды стран'!$A$2:$A$7, MATCH(F12, 'коды стран'!$B$2:$B$7, 0)) -> Россия | H12: Россия | I12: =LEFT(Таблица8[[#This Row],[ФИО]],(M12-1)) -> Агата | J12: =MID(Таблица8[[#This Row],[ФИО]],M12,(N12-M12)) -> Геннадьевна | K12: =RIGHT(Таблица8[[#This Row],[ФИО]],(O12-N12)) -> Колесникова | M12: =FIND(" ",Таблица8[[#This Row],[ФИО]],2) -> 6 | N12: =FIND(" ",Таблица8[[#This Row],[ФИО]],(M12+1)) -> 18 | O12: =LEN(Таблица8[[#This Row],[ФИО]]) -> 29 | Q12: =LEFT(Таблица8[[#This Row],[ФИО]],(M12-1)) -> Агата | R12: Колесникова | S12: Геннадьевна
A13: 443 | B13: +7 210-575-0459 | C13: Агата Олеговна Мартынова | D13: да | E13: 44649 | F13: =LEFT(B13,LEN(B13)-13) -> +7 | G13: =INDEX('коды стран'!$A$2:$A$7, MATCH(F13, 'коды стран'!$B$2:$B$7, 0)) -> Россия | H13: Россия | I13: =LEFT(Таблица8[[#This Row],[ФИО]],(M13-1)) -> Агата | J13: =MID(Таблица8[[#This Row],[ФИО]],M13,(N13-M13)) -> Олеговна | K13: =RIGHT(Таблица8[[#This Row],[ФИО]],(O13-N13)) -> Мартынова | M13: =FIND(" ",Таблица8[[#This Row],[ФИО]],2) -> 6 | N13: =FIND(" ",Таблица8[[#This Row],[ФИО]],(M13+1)) -> 15 | O13: =LEN(Таблица8[[#This Row],[ФИО]]) -> 24 | Q13: =LEFT(Таблица8[[#This Row],[ФИО]],(M13-1)) -> Агата | R13: Мартынова | S13: Олеговна
A14: 332 | B14: +998 350-816-0031 | C14: Агата Юрьевна Галкина | D14: нет | E14: 44858 | F14: =LEFT(B14,LEN(B14)-13) -> +998 | G14: =INDEX('коды стран'!$A$2:$A$7, MATCH(F14, 'коды стран'!$B$2:$B$7, 0)) -> Узбекистан | H14: Узбекистан | I14: =LEFT(Таблица8[[#This Row],[ФИО]],(M14-1)) -> Агата | J14: =MID(Таблица8[[#This Row],[ФИО]],M14,(N14-M14)) -> Юрьевна | K14: =RIGHT(Таблица8[[#This Row],[ФИО]],(O14-N14)) -> Галкина | M14: =FIND(" ",Таблица8[[#This Row],[ФИО]],2) -> 6 | N14: =FIND(" ",Таблица8[[#This Row],[ФИО]],(M14+1)) -> 14 | O14: =LEN(Таблица8[[#This Row],[ФИО]]) -> 21 | Q14: =LEFT(Таблица8[[#This Row],[ФИО]],(M14-1)) -> Агата | R14: Галкина | S14: Юрьевна
